[2025-01-10 05:46:00 +0000] [37131] [INFO] Starting gunicorn 23.0.0
[2025-01-10 05:46:00 +0000] [37131] [INFO] Listening at: http://127.0.0.1:8000 (37131)
[2025-01-10 05:46:00 +0000] [37131] [INFO] Using worker: sync
[2025-01-10 05:46:00 +0000] [37133] [INFO] Booting worker with pid: 37133
[2025-01-10 05:46:00 +0000] [37136] [INFO] Booting worker with pid: 37136
[2025-01-10 05:46:00 +0000] [37137] [INFO] Booting worker with pid: 37137
[2025-01-10 05:46:00 +0000] [37138] [INFO] Booting worker with pid: 37138
[2025-01-10 05:46:02 +0000] [37133] [INFO] Worker exiting (pid: 37133)
[2025-01-10 05:46:02 +0000] [37137] [INFO] Worker exiting (pid: 37137)
[2025-01-10 05:46:02 +0000] [37136] [INFO] Worker exiting (pid: 37136)
[2025-01-10 05:46:02 +0000] [37138] [INFO] Worker exiting (pid: 37138)
[2025-01-10 05:46:02 +0000] [37131] [ERROR] Worker (pid:37133) exited with code 4
[2025-01-10 05:46:02 +0000] [37131] [ERROR] Worker (pid:37137) was sent SIGTERM!
[2025-01-10 05:46:02 +0000] [37131] [ERROR] Worker (pid:37136) was sent SIGTERM!
[2025-01-10 05:46:02 +0000] [37131] [ERROR] Worker (pid:37138) was sent SIGTERM!
[2025-01-10 05:46:02 +0000] [37131] [ERROR] Shutting down: Master
[2025-01-10 05:46:02 +0000] [37131] [ERROR] Reason: App failed to load.
[2025-01-10 05:48:44 +0000] [38281] [INFO] Starting gunicorn 23.0.0
[2025-01-10 05:48:44 +0000] [38281] [INFO] Listening at: http://127.0.0.1:8000 (38281)
[2025-01-10 05:48:44 +0000] [38281] [INFO] Using worker: sync
[2025-01-10 05:48:44 +0000] [38283] [INFO] Booting worker with pid: 38283
[2025-01-10 05:48:44 +0000] [38285] [INFO] Booting worker with pid: 38285
[2025-01-10 05:48:44 +0000] [38287] [INFO] Booting worker with pid: 38287
[2025-01-10 05:48:44 +0000] [38288] [INFO] Booting worker with pid: 38288
[2025-01-10 05:48:46 +0000] [38283] [INFO] Worker exiting (pid: 38283)
[2025-01-10 05:48:46 +0000] [38285] [INFO] Worker exiting (pid: 38285)
[2025-01-10 05:48:46 +0000] [38287] [INFO] Worker exiting (pid: 38287)
[2025-01-10 05:48:46 +0000] [38288] [INFO] Worker exiting (pid: 38288)
[2025-01-10 05:48:47 +0000] [38281] [ERROR] Worker (pid:38283) exited with code 4
[2025-01-10 05:48:47 +0000] [38281] [ERROR] Worker (pid:38285) was sent SIGTERM!
[2025-01-10 05:48:47 +0000] [38281] [ERROR] Worker (pid:38288) was sent SIGTERM!
[2025-01-10 05:48:47 +0000] [38281] [ERROR] Worker (pid:38287) was sent SIGTERM!
[2025-01-10 05:48:47 +0000] [38281] [ERROR] Shutting down: Master
[2025-01-10 05:48:47 +0000] [38281] [ERROR] Reason: App failed to load.
[2025-01-10 05:51:11 +0000] [40144] [INFO] Starting gunicorn 23.0.0
[2025-01-10 05:51:11 +0000] [40144] [INFO] Listening at: http://127.0.0.1:8000 (40144)
[2025-01-10 05:51:11 +0000] [40144] [INFO] Using worker: sync
[2025-01-10 05:51:11 +0000] [40145] [INFO] Booting worker with pid: 40145
[2025-01-10 05:51:11 +0000] [40148] [INFO] Booting worker with pid: 40148
[2025-01-10 05:51:11 +0000] [40149] [INFO] Booting worker with pid: 40149
[2025-01-10 05:51:11 +0000] [40150] [INFO] Booting worker with pid: 40150
[2025-01-10 05:57:00 +0000] [40144] [INFO] Handling signal: term
[2025-01-10 05:57:00 +0000] [40145] [INFO] Worker exiting (pid: 40145)
[2025-01-10 05:57:00 +0000] [40148] [INFO] Worker exiting (pid: 40148)
[2025-01-10 05:57:00 +0000] [40149] [INFO] Worker exiting (pid: 40149)
[2025-01-10 05:57:00 +0000] [40150] [INFO] Worker exiting (pid: 40150)
[2025-01-10 05:57:00 +0000] [40144] [ERROR] Worker (pid:40145) was sent SIGTERM!
[2025-01-10 05:57:00 +0000] [40144] [ERROR] Worker (pid:40148) was sent SIGTERM!
[2025-01-10 05:57:00 +0000] [40144] [ERROR] Worker (pid:40149) was sent SIGTERM!
[2025-01-10 05:57:00 +0000] [40144] [INFO] Shutting down: Master
[2025-01-10 05:57:05 +0000] [43620] [INFO] Starting gunicorn 23.0.0
[2025-01-10 05:57:05 +0000] [43620] [INFO] Listening at: http://127.0.0.1:8000 (43620)
[2025-01-10 05:57:05 +0000] [43620] [INFO] Using worker: sync
[2025-01-10 05:57:05 +0000] [43622] [INFO] Booting worker with pid: 43622
[2025-01-10 05:57:05 +0000] [43625] [INFO] Booting worker with pid: 43625
[2025-01-10 05:57:05 +0000] [43626] [INFO] Booting worker with pid: 43626
[2025-01-10 05:57:05 +0000] [43627] [INFO] Booting worker with pid: 43627
[2025-01-10 05:57:07 +0000] [43622] [ERROR] Exception in worker process
Traceback (most recent call last):
  File "/home/ec2-user/test_form/.venv/lib64/python3.12/site-packages/gunicorn/arbiter.py", line 608, in spawn_worker
    worker.init_process()
  File "/home/ec2-user/test_form/.venv/lib64/python3.12/site-packages/gunicorn/workers/base.py", line 135, in init_process
    self.load_wsgi()
  File "/home/ec2-user/test_form/.venv/lib64/python3.12/site-packages/gunicorn/workers/base.py", line 147, in load_wsgi
    self.wsgi = self.app.wsgi()
                ^^^^^^^^^^^^^^^
  File "/home/ec2-user/test_form/.venv/lib64/python3.12/site-packages/gunicorn/app/base.py", line 66, in wsgi
    self.callable = self.load()
                    ^^^^^^^^^^^
  File "/home/ec2-user/test_form/.venv/lib64/python3.12/site-packages/gunicorn/app/wsgiapp.py", line 57, in load
    return self.load_wsgiapp()
           ^^^^^^^^^^^^^^^^^^^
  File "/home/ec2-user/test_form/.venv/lib64/python3.12/site-packages/gunicorn/app/wsgiapp.py", line 47, in load_wsgiapp
    return util.import_app(self.app_uri)
           ^^^^^^^^^^^^^^^^^^^^^^^^^^^^^
  File "/home/ec2-user/test_form/.venv/lib64/python3.12/site-packages/gunicorn/util.py", line 370, in import_app
    mod = importlib.import_module(module)
          ^^^^^^^^^^^^^^^^^^^^^^^^^^^^^^^
  File "/usr/lib64/python3.12/importlib/__init__.py", line 90, in import_module
    return _bootstrap._gcd_import(name[level:], package, level)
           ^^^^^^^^^^^^^^^^^^^^^^^^^^^^^^^^^^^^^^^^^^^^^^^^^^^^
  File "<frozen importlib._bootstrap>", line 1387, in _gcd_import
  File "<frozen importlib._bootstrap>", line 1360, in _find_and_load
  File "<frozen importlib._bootstrap>", line 1331, in _find_and_load_unlocked
  File "<frozen importlib._bootstrap>", line 935, in _load_unlocked
  File "<frozen importlib._bootstrap_external>", line 995, in exec_module
  File "<frozen importlib._bootstrap>", line 488, in _call_with_frames_removed
  File "/home/ec2-user/test_form/wsgi.py", line 1, in <module>
    from app import create_app
  File "/home/ec2-user/test_form/app/__init__.py", line 4, in <module>
    from app.routes import routes
  File "/home/ec2-user/test_form/app/routes.py", line 2, in <module>
    from app.views import users
ModuleNotFoundError: No module named 'app.views'
[2025-01-10 05:57:07 +0000] [43622] [INFO] Worker exiting (pid: 43622)
[2025-01-10 05:57:07 +0000] [43626] [ERROR] Exception in worker process
Traceback (most recent call last):
  File "/home/ec2-user/test_form/.venv/lib64/python3.12/site-packages/gunicorn/arbiter.py", line 608, in spawn_worker
    worker.init_process()
  File "/home/ec2-user/test_form/.venv/lib64/python3.12/site-packages/gunicorn/workers/base.py", line 135, in init_process
    self.load_wsgi()
  File "/home/ec2-user/test_form/.venv/lib64/python3.12/site-packages/gunicorn/workers/base.py", line 147, in load_wsgi
    self.wsgi = self.app.wsgi()
                ^^^^^^^^^^^^^^^
  File "/home/ec2-user/test_form/.venv/lib64/python3.12/site-packages/gunicorn/app/base.py", line 66, in wsgi
    self.callable = self.load()
                    ^^^^^^^^^^^
  File "/home/ec2-user/test_form/.venv/lib64/python3.12/site-packages/gunicorn/app/wsgiapp.py", line 57, in load
    return self.load_wsgiapp()
           ^^^^^^^^^^^^^^^^^^^
  File "/home/ec2-user/test_form/.venv/lib64/python3.12/site-packages/gunicorn/app/wsgiapp.py", line 47, in load_wsgiapp
    return util.import_app(self.app_uri)
           ^^^^^^^^^^^^^^^^^^^^^^^^^^^^^
  File "/home/ec2-user/test_form/.venv/lib64/python3.12/site-packages/gunicorn/util.py", line 370, in import_app
    mod = importlib.import_module(module)
          ^^^^^^^^^^^^^^^^^^^^^^^^^^^^^^^
  File "/usr/lib64/python3.12/importlib/__init__.py", line 90, in import_module
    return _bootstrap._gcd_import(name[level:], package, level)
           ^^^^^^^^^^^^^^^^^^^^^^^^^^^^^^^^^^^^^^^^^^^^^^^^^^^^
  File "<frozen importlib._bootstrap>", line 1387, in _gcd_import
  File "<frozen importlib._bootstrap>", line 1360, in _find_and_load
  File "<frozen importlib._bootstrap>", line 1331, in _find_and_load_unlocked
  File "<frozen importlib._bootstrap>", line 935, in _load_unlocked
  File "<frozen importlib._bootstrap_external>", line 995, in exec_module
  File "<frozen importlib._bootstrap>", line 488, in _call_with_frames_removed
  File "/home/ec2-user/test_form/wsgi.py", line 1, in <module>
    from app import create_app
  File "/home/ec2-user/test_form/app/__init__.py", line 4, in <module>
    from app.routes import routes
  File "/home/ec2-user/test_form/app/routes.py", line 2, in <module>
    from app.views import users
ModuleNotFoundError: No module named 'app.views'
[2025-01-10 05:57:07 +0000] [43626] [INFO] Worker exiting (pid: 43626)
[2025-01-10 05:57:07 +0000] [43625] [ERROR] Exception in worker process
Traceback (most recent call last):
  File "/home/ec2-user/test_form/.venv/lib64/python3.12/site-packages/gunicorn/arbiter.py", line 608, in spawn_worker
    worker.init_process()
  File "/home/ec2-user/test_form/.venv/lib64/python3.12/site-packages/gunicorn/workers/base.py", line 135, in init_process
    self.load_wsgi()
  File "/home/ec2-user/test_form/.venv/lib64/python3.12/site-packages/gunicorn/workers/base.py", line 147, in load_wsgi
    self.wsgi = self.app.wsgi()
                ^^^^^^^^^^^^^^^
  File "/home/ec2-user/test_form/.venv/lib64/python3.12/site-packages/gunicorn/app/base.py", line 66, in wsgi
    self.callable = self.load()
                    ^^^^^^^^^^^
  File "/home/ec2-user/test_form/.venv/lib64/python3.12/site-packages/gunicorn/app/wsgiapp.py", line 57, in load
    return self.load_wsgiapp()
           ^^^^^^^^^^^^^^^^^^^
  File "/home/ec2-user/test_form/.venv/lib64/python3.12/site-packages/gunicorn/app/wsgiapp.py", line 47, in load_wsgiapp
    return util.import_app(self.app_uri)
           ^^^^^^^^^^^^^^^^^^^^^^^^^^^^^
  File "/home/ec2-user/test_form/.venv/lib64/python3.12/site-packages/gunicorn/util.py", line 370, in import_app
    mod = importlib.import_module(module)
          ^^^^^^^^^^^^^^^^^^^^^^^^^^^^^^^
  File "/usr/lib64/python3.12/importlib/__init__.py", line 90, in import_module
    return _bootstrap._gcd_import(name[level:], package, level)
           ^^^^^^^^^^^^^^^^^^^^^^^^^^^^^^^^^^^^^^^^^^^^^^^^^^^^
  File "<frozen importlib._bootstrap>", line 1387, in _gcd_import
  File "<frozen importlib._bootstrap>", line 1360, in _find_and_load
  File "<frozen importlib._bootstrap>", line 1331, in _find_and_load_unlocked
  File "<frozen importlib._bootstrap>", line 935, in _load_unlocked
  File "<frozen importlib._bootstrap_external>", line 995, in exec_module
  File "<frozen importlib._bootstrap>", line 488, in _call_with_frames_removed
  File "/home/ec2-user/test_form/wsgi.py", line 1, in <module>
    from app import create_app
  File "/home/ec2-user/test_form/app/__init__.py", line 4, in <module>
    from app.routes import routes
  File "/home/ec2-user/test_form/app/routes.py", line 2, in <module>
    from app.views import users
ModuleNotFoundError: No module named 'app.views'
[2025-01-10 05:57:07 +0000] [43625] [INFO] Worker exiting (pid: 43625)
[2025-01-10 05:57:07 +0000] [43627] [ERROR] Exception in worker process
Traceback (most recent call last):
  File "/home/ec2-user/test_form/.venv/lib64/python3.12/site-packages/gunicorn/arbiter.py", line 608, in spawn_worker
    worker.init_process()
  File "/home/ec2-user/test_form/.venv/lib64/python3.12/site-packages/gunicorn/workers/base.py", line 135, in init_process
    self.load_wsgi()
  File "/home/ec2-user/test_form/.venv/lib64/python3.12/site-packages/gunicorn/workers/base.py", line 147, in load_wsgi
    self.wsgi = self.app.wsgi()
                ^^^^^^^^^^^^^^^
  File "/home/ec2-user/test_form/.venv/lib64/python3.12/site-packages/gunicorn/app/base.py", line 66, in wsgi
    self.callable = self.load()
                    ^^^^^^^^^^^
  File "/home/ec2-user/test_form/.venv/lib64/python3.12/site-packages/gunicorn/app/wsgiapp.py", line 57, in load
    return self.load_wsgiapp()
           ^^^^^^^^^^^^^^^^^^^
  File "/home/ec2-user/test_form/.venv/lib64/python3.12/site-packages/gunicorn/app/wsgiapp.py", line 47, in load_wsgiapp
    return util.import_app(self.app_uri)
           ^^^^^^^^^^^^^^^^^^^^^^^^^^^^^
  File "/home/ec2-user/test_form/.venv/lib64/python3.12/site-packages/gunicorn/util.py", line 370, in import_app
    mod = importlib.import_module(module)
          ^^^^^^^^^^^^^^^^^^^^^^^^^^^^^^^
  File "/usr/lib64/python3.12/importlib/__init__.py", line 90, in import_module
    return _bootstrap._gcd_import(name[level:], package, level)
           ^^^^^^^^^^^^^^^^^^^^^^^^^^^^^^^^^^^^^^^^^^^^^^^^^^^^
  File "<frozen importlib._bootstrap>", line 1387, in _gcd_import
  File "<frozen importlib._bootstrap>", line 1360, in _find_and_load
  File "<frozen importlib._bootstrap>", line 1331, in _find_and_load_unlocked
  File "<frozen importlib._bootstrap>", line 935, in _load_unlocked
  File "<frozen importlib._bootstrap_external>", line 995, in exec_module
  File "<frozen importlib._bootstrap>", line 488, in _call_with_frames_removed
  File "/home/ec2-user/test_form/wsgi.py", line 1, in <module>
    from app import create_app
  File "/home/ec2-user/test_form/app/__init__.py", line 4, in <module>
    from app.routes import routes
  File "/home/ec2-user/test_form/app/routes.py", line 2, in <module>
    from app.views import users
ModuleNotFoundError: No module named 'app.views'
[2025-01-10 05:57:07 +0000] [43627] [INFO] Worker exiting (pid: 43627)
[2025-01-10 05:57:07 +0000] [43620] [ERROR] Worker (pid:43622) exited with code 3
[2025-01-10 05:57:07 +0000] [43620] [ERROR] Worker (pid:43627) was sent SIGTERM!
[2025-01-10 05:57:07 +0000] [43620] [ERROR] Worker (pid:43625) was sent SIGTERM!
[2025-01-10 05:57:07 +0000] [43620] [ERROR] Worker (pid:43626) was sent SIGTERM!
[2025-01-10 05:57:07 +0000] [43620] [ERROR] Shutting down: Master
[2025-01-10 05:57:07 +0000] [43620] [ERROR] Reason: Worker failed to boot.
[2025-01-10 05:58:09 +0000] [44345] [INFO] Starting gunicorn 23.0.0
[2025-01-10 05:58:09 +0000] [44345] [INFO] Listening at: http://127.0.0.1:8000 (44345)
[2025-01-10 05:58:09 +0000] [44345] [INFO] Using worker: sync
[2025-01-10 05:58:09 +0000] [44347] [INFO] Booting worker with pid: 44347
[2025-01-10 05:58:09 +0000] [44348] [INFO] Booting worker with pid: 44348
[2025-01-10 05:58:09 +0000] [44351] [INFO] Booting worker with pid: 44351
[2025-01-10 05:58:09 +0000] [44352] [INFO] Booting worker with pid: 44352
[2025-01-10 06:53:46 +0000] [44345] [INFO] Handling signal: term
[2025-01-10 06:53:46 +0000] [44347] [INFO] Worker exiting (pid: 44347)
[2025-01-10 06:53:46 +0000] [44348] [INFO] Worker exiting (pid: 44348)
[2025-01-10 06:53:46 +0000] [44351] [INFO] Worker exiting (pid: 44351)
[2025-01-10 06:53:46 +0000] [44352] [INFO] Worker exiting (pid: 44352)
[2025-01-10 06:53:46 +0000] [44345] [ERROR] Worker (pid:44347) was sent SIGTERM!
[2025-01-10 06:53:46 +0000] [44345] [ERROR] Worker (pid:44348) was sent SIGTERM!
[2025-01-10 06:53:47 +0000] [44345] [ERROR] Worker (pid:44351) was sent SIGTERM!
[2025-01-10 06:53:47 +0000] [44345] [INFO] Shutting down: Master
[2025-01-10 06:54:14 +0000] [53274] [INFO] Starting gunicorn 23.0.0
[2025-01-10 06:54:14 +0000] [53274] [INFO] Listening at: http://127.0.0.1:8000 (53274)
[2025-01-10 06:54:14 +0000] [53274] [INFO] Using worker: sync
[2025-01-10 06:54:14 +0000] [53276] [INFO] Booting worker with pid: 53276
[2025-01-10 06:54:14 +0000] [53277] [INFO] Booting worker with pid: 53277
[2025-01-10 06:54:14 +0000] [53279] [INFO] Booting worker with pid: 53279
[2025-01-10 06:54:15 +0000] [53281] [INFO] Booting worker with pid: 53281
[2025-01-10 07:04:10 +0000] [53274] [INFO] Handling signal: term
[2025-01-10 07:04:10 +0000] [53276] [INFO] Worker exiting (pid: 53276)
[2025-01-10 07:04:10 +0000] [53277] [INFO] Worker exiting (pid: 53277)
[2025-01-10 07:04:10 +0000] [53279] [INFO] Worker exiting (pid: 53279)
[2025-01-10 07:04:10 +0000] [53281] [INFO] Worker exiting (pid: 53281)
[2025-01-10 07:04:10 +0000] [53274] [ERROR] Worker (pid:53276) was sent SIGTERM!
[2025-01-10 07:04:11 +0000] [53274] [ERROR] Worker (pid:53277) was sent SIGTERM!
[2025-01-10 07:04:11 +0000] [53274] [ERROR] Worker (pid:53279) was sent SIGTERM!
[2025-01-10 07:04:11 +0000] [53274] [INFO] Shutting down: Master
[2025-01-10 07:04:15 +0000] [55041] [INFO] Starting gunicorn 23.0.0
[2025-01-10 07:04:15 +0000] [55041] [INFO] Listening at: http://127.0.0.1:8000 (55041)
[2025-01-10 07:04:15 +0000] [55041] [INFO] Using worker: sync
[2025-01-10 07:04:15 +0000] [55043] [INFO] Booting worker with pid: 55043
[2025-01-10 07:04:15 +0000] [55046] [INFO] Booting worker with pid: 55046
[2025-01-10 07:04:15 +0000] [55047] [INFO] Booting worker with pid: 55047
[2025-01-10 07:04:15 +0000] [55048] [INFO] Booting worker with pid: 55048
[2025-01-10 07:04:17 +0000] [55043] [ERROR] Exception in worker process
Traceback (most recent call last):
  File "/home/ec2-user/test_form/.venv/lib64/python3.12/site-packages/gunicorn/arbiter.py", line 608, in spawn_worker
    worker.init_process()
  File "/home/ec2-user/test_form/.venv/lib64/python3.12/site-packages/gunicorn/workers/base.py", line 135, in init_process
    self.load_wsgi()
  File "/home/ec2-user/test_form/.venv/lib64/python3.12/site-packages/gunicorn/workers/base.py", line 147, in load_wsgi
    self.wsgi = self.app.wsgi()
                ^^^^^^^^^^^^^^^
  File "/home/ec2-user/test_form/.venv/lib64/python3.12/site-packages/gunicorn/app/base.py", line 66, in wsgi
    self.callable = self.load()
                    ^^^^^^^^^^^
  File "/home/ec2-user/test_form/.venv/lib64/python3.12/site-packages/gunicorn/app/wsgiapp.py", line 57, in load
    return self.load_wsgiapp()
           ^^^^^^^^^^^^^^^^^^^
  File "/home/ec2-user/test_form/.venv/lib64/python3.12/site-packages/gunicorn/app/wsgiapp.py", line 47, in load_wsgiapp
    return util.import_app(self.app_uri)
           ^^^^^^^^^^^^^^^^^^^^^^^^^^^^^
  File "/home/ec2-user/test_form/.venv/lib64/python3.12/site-packages/gunicorn/util.py", line 370, in import_app
    mod = importlib.import_module(module)
          ^^^^^^^^^^^^^^^^^^^^^^^^^^^^^^^
  File "/usr/lib64/python3.12/importlib/__init__.py", line 90, in import_module
    return _bootstrap._gcd_import(name[level:], package, level)
           ^^^^^^^^^^^^^^^^^^^^^^^^^^^^^^^^^^^^^^^^^^^^^^^^^^^^
  File "<frozen importlib._bootstrap>", line 1387, in _gcd_import
  File "<frozen importlib._bootstrap>", line 1360, in _find_and_load
  File "<frozen importlib._bootstrap>", line 1331, in _find_and_load_unlocked
  File "<frozen importlib._bootstrap>", line 935, in _load_unlocked
  File "<frozen importlib._bootstrap_external>", line 995, in exec_module
  File "<frozen importlib._bootstrap>", line 488, in _call_with_frames_removed
  File "/home/ec2-user/test_form/wsgi.py", line 1, in <module>
    from app import create_app
  File "/home/ec2-user/test_form/app/__init__.py", line 4, in <module>
    from app.routes import routes
  File "/home/ec2-user/test_form/app/routes.py", line 2, in <module>
    from app.services import users, images, quetions
ImportError: cannot import name 'quetions' from 'app.services' (unknown location)
[2025-01-10 07:04:17 +0000] [55043] [INFO] Worker exiting (pid: 55043)
[2025-01-10 07:04:17 +0000] [55047] [ERROR] Exception in worker process
Traceback (most recent call last):
  File "/home/ec2-user/test_form/.venv/lib64/python3.12/site-packages/gunicorn/arbiter.py", line 608, in spawn_worker
    worker.init_process()
  File "/home/ec2-user/test_form/.venv/lib64/python3.12/site-packages/gunicorn/workers/base.py", line 135, in init_process
    self.load_wsgi()
  File "/home/ec2-user/test_form/.venv/lib64/python3.12/site-packages/gunicorn/workers/base.py", line 147, in load_wsgi
    self.wsgi = self.app.wsgi()
                ^^^^^^^^^^^^^^^
  File "/home/ec2-user/test_form/.venv/lib64/python3.12/site-packages/gunicorn/app/base.py", line 66, in wsgi
    self.callable = self.load()
                    ^^^^^^^^^^^
  File "/home/ec2-user/test_form/.venv/lib64/python3.12/site-packages/gunicorn/app/wsgiapp.py", line 57, in load
    return self.load_wsgiapp()
           ^^^^^^^^^^^^^^^^^^^
  File "/home/ec2-user/test_form/.venv/lib64/python3.12/site-packages/gunicorn/app/wsgiapp.py", line 47, in load_wsgiapp
    return util.import_app(self.app_uri)
           ^^^^^^^^^^^^^^^^^^^^^^^^^^^^^
  File "/home/ec2-user/test_form/.venv/lib64/python3.12/site-packages/gunicorn/util.py", line 370, in import_app
    mod = importlib.import_module(module)
          ^^^^^^^^^^^^^^^^^^^^^^^^^^^^^^^
  File "/usr/lib64/python3.12/importlib/__init__.py", line 90, in import_module
    return _bootstrap._gcd_import(name[level:], package, level)
           ^^^^^^^^^^^^^^^^^^^^^^^^^^^^^^^^^^^^^^^^^^^^^^^^^^^^
  File "<frozen importlib._bootstrap>", line 1387, in _gcd_import
  File "<frozen importlib._bootstrap>", line 1360, in _find_and_load
  File "<frozen importlib._bootstrap>", line 1331, in _find_and_load_unlocked
  File "<frozen importlib._bootstrap>", line 935, in _load_unlocked
  File "<frozen importlib._bootstrap_external>", line 995, in exec_module
  File "<frozen importlib._bootstrap>", line 488, in _call_with_frames_removed
  File "/home/ec2-user/test_form/wsgi.py", line 1, in <module>
    from app import create_app
  File "/home/ec2-user/test_form/app/__init__.py", line 4, in <module>
    from app.routes import routes
  File "/home/ec2-user/test_form/app/routes.py", line 2, in <module>
    from app.services import users, images, quetions
ImportError: cannot import name 'quetions' from 'app.services' (unknown location)
[2025-01-10 07:04:17 +0000] [55047] [INFO] Worker exiting (pid: 55047)
[2025-01-10 07:04:17 +0000] [55046] [ERROR] Exception in worker process
Traceback (most recent call last):
  File "/home/ec2-user/test_form/.venv/lib64/python3.12/site-packages/gunicorn/arbiter.py", line 608, in spawn_worker
    worker.init_process()
  File "/home/ec2-user/test_form/.venv/lib64/python3.12/site-packages/gunicorn/workers/base.py", line 135, in init_process
    self.load_wsgi()
  File "/home/ec2-user/test_form/.venv/lib64/python3.12/site-packages/gunicorn/workers/base.py", line 147, in load_wsgi
    self.wsgi = self.app.wsgi()
                ^^^^^^^^^^^^^^^
  File "/home/ec2-user/test_form/.venv/lib64/python3.12/site-packages/gunicorn/app/base.py", line 66, in wsgi
    self.callable = self.load()
                    ^^^^^^^^^^^
  File "/home/ec2-user/test_form/.venv/lib64/python3.12/site-packages/gunicorn/app/wsgiapp.py", line 57, in load
    return self.load_wsgiapp()
           ^^^^^^^^^^^^^^^^^^^
  File "/home/ec2-user/test_form/.venv/lib64/python3.12/site-packages/gunicorn/app/wsgiapp.py", line 47, in load_wsgiapp
    return util.import_app(self.app_uri)
           ^^^^^^^^^^^^^^^^^^^^^^^^^^^^^
  File "/home/ec2-user/test_form/.venv/lib64/python3.12/site-packages/gunicorn/util.py", line 370, in import_app
    mod = importlib.import_module(module)
          ^^^^^^^^^^^^^^^^^^^^^^^^^^^^^^^
  File "/usr/lib64/python3.12/importlib/__init__.py", line 90, in import_module
    return _bootstrap._gcd_import(name[level:], package, level)
           ^^^^^^^^^^^^^^^^^^^^^^^^^^^^^^^^^^^^^^^^^^^^^^^^^^^^
  File "<frozen importlib._bootstrap>", line 1387, in _gcd_import
  File "<frozen importlib._bootstrap>", line 1360, in _find_and_load
  File "<frozen importlib._bootstrap>", line 1331, in _find_and_load_unlocked
  File "<frozen importlib._bootstrap>", line 935, in _load_unlocked
  File "<frozen importlib._bootstrap_external>", line 995, in exec_module
  File "<frozen importlib._bootstrap>", line 488, in _call_with_frames_removed
  File "/home/ec2-user/test_form/wsgi.py", line 1, in <module>
    from app import create_app
  File "/home/ec2-user/test_form/app/__init__.py", line 4, in <module>
    from app.routes import routes
  File "/home/ec2-user/test_form/app/routes.py", line 2, in <module>
    from app.services import users, images, quetions
ImportError: cannot import name 'quetions' from 'app.services' (unknown location)
[2025-01-10 07:04:17 +0000] [55046] [INFO] Worker exiting (pid: 55046)
[2025-01-10 07:04:17 +0000] [55048] [ERROR] Exception in worker process
Traceback (most recent call last):
  File "/home/ec2-user/test_form/.venv/lib64/python3.12/site-packages/gunicorn/arbiter.py", line 608, in spawn_worker
    worker.init_process()
  File "/home/ec2-user/test_form/.venv/lib64/python3.12/site-packages/gunicorn/workers/base.py", line 135, in init_process
    self.load_wsgi()
  File "/home/ec2-user/test_form/.venv/lib64/python3.12/site-packages/gunicorn/workers/base.py", line 147, in load_wsgi
    self.wsgi = self.app.wsgi()
                ^^^^^^^^^^^^^^^
  File "/home/ec2-user/test_form/.venv/lib64/python3.12/site-packages/gunicorn/app/base.py", line 66, in wsgi
    self.callable = self.load()
                    ^^^^^^^^^^^
  File "/home/ec2-user/test_form/.venv/lib64/python3.12/site-packages/gunicorn/app/wsgiapp.py", line 57, in load
    return self.load_wsgiapp()
           ^^^^^^^^^^^^^^^^^^^
  File "/home/ec2-user/test_form/.venv/lib64/python3.12/site-packages/gunicorn/app/wsgiapp.py", line 47, in load_wsgiapp
    return util.import_app(self.app_uri)
           ^^^^^^^^^^^^^^^^^^^^^^^^^^^^^
  File "/home/ec2-user/test_form/.venv/lib64/python3.12/site-packages/gunicorn/util.py", line 370, in import_app
    mod = importlib.import_module(module)
          ^^^^^^^^^^^^^^^^^^^^^^^^^^^^^^^
  File "/usr/lib64/python3.12/importlib/__init__.py", line 90, in import_module
    return _bootstrap._gcd_import(name[level:], package, level)
           ^^^^^^^^^^^^^^^^^^^^^^^^^^^^^^^^^^^^^^^^^^^^^^^^^^^^
  File "<frozen importlib._bootstrap>", line 1387, in _gcd_import
  File "<frozen importlib._bootstrap>", line 1360, in _find_and_load
  File "<frozen importlib._bootstrap>", line 1331, in _find_and_load_unlocked
  File "<frozen importlib._bootstrap>", line 935, in _load_unlocked
  File "<frozen importlib._bootstrap_external>", line 995, in exec_module
  File "<frozen importlib._bootstrap>", line 488, in _call_with_frames_removed
  File "/home/ec2-user/test_form/wsgi.py", line 1, in <module>
    from app import create_app
  File "/home/ec2-user/test_form/app/__init__.py", line 4, in <module>
    from app.routes import routes
  File "/home/ec2-user/test_form/app/routes.py", line 2, in <module>
    from app.services import users, images, quetions
ImportError: cannot import name 'quetions' from 'app.services' (unknown location)
[2025-01-10 07:04:17 +0000] [55048] [INFO] Worker exiting (pid: 55048)
[2025-01-10 07:04:17 +0000] [55041] [ERROR] Worker (pid:55043) exited with code 3
[2025-01-10 07:04:17 +0000] [55041] [ERROR] Worker (pid:55047) was sent SIGTERM!
[2025-01-10 07:04:17 +0000] [55041] [ERROR] Worker (pid:55048) was sent SIGTERM!
[2025-01-10 07:04:17 +0000] [55041] [ERROR] Worker (pid:55046) was sent SIGTERM!
[2025-01-10 07:04:17 +0000] [55041] [ERROR] Shutting down: Master
[2025-01-10 07:04:17 +0000] [55041] [ERROR] Reason: Worker failed to boot.
[2025-01-10 07:07:27 +0000] [55517] [INFO] Starting gunicorn 23.0.0
[2025-01-10 07:07:27 +0000] [55517] [INFO] Listening at: http://127.0.0.1:8000 (55517)
[2025-01-10 07:07:27 +0000] [55517] [INFO] Using worker: sync
[2025-01-10 07:07:27 +0000] [55519] [INFO] Booting worker with pid: 55519
[2025-01-10 07:07:27 +0000] [55522] [INFO] Booting worker with pid: 55522
[2025-01-10 07:07:27 +0000] [55523] [INFO] Booting worker with pid: 55523
[2025-01-10 07:07:27 +0000] [55524] [INFO] Booting worker with pid: 55524
[2025-01-10 07:07:29 +0000] [55519] [ERROR] Exception in worker process
Traceback (most recent call last):
  File "/home/ec2-user/test_form/.venv/lib64/python3.12/site-packages/gunicorn/arbiter.py", line 608, in spawn_worker
    worker.init_process()
  File "/home/ec2-user/test_form/.venv/lib64/python3.12/site-packages/gunicorn/workers/base.py", line 135, in init_process
    self.load_wsgi()
  File "/home/ec2-user/test_form/.venv/lib64/python3.12/site-packages/gunicorn/workers/base.py", line 147, in load_wsgi
    self.wsgi = self.app.wsgi()
                ^^^^^^^^^^^^^^^
  File "/home/ec2-user/test_form/.venv/lib64/python3.12/site-packages/gunicorn/app/base.py", line 66, in wsgi
    self.callable = self.load()
                    ^^^^^^^^^^^
  File "/home/ec2-user/test_form/.venv/lib64/python3.12/site-packages/gunicorn/app/wsgiapp.py", line 57, in load
    return self.load_wsgiapp()
           ^^^^^^^^^^^^^^^^^^^
  File "/home/ec2-user/test_form/.venv/lib64/python3.12/site-packages/gunicorn/app/wsgiapp.py", line 47, in load_wsgiapp
    return util.import_app(self.app_uri)
           ^^^^^^^^^^^^^^^^^^^^^^^^^^^^^
  File "/home/ec2-user/test_form/.venv/lib64/python3.12/site-packages/gunicorn/util.py", line 370, in import_app
    mod = importlib.import_module(module)
          ^^^^^^^^^^^^^^^^^^^^^^^^^^^^^^^
  File "/usr/lib64/python3.12/importlib/__init__.py", line 90, in import_module
    return _bootstrap._gcd_import(name[level:], package, level)
           ^^^^^^^^^^^^^^^^^^^^^^^^^^^^^^^^^^^^^^^^^^^^^^^^^^^^
  File "<frozen importlib._bootstrap>", line 1387, in _gcd_import
  File "<frozen importlib._bootstrap>", line 1360, in _find_and_load
  File "<frozen importlib._bootstrap>", line 1331, in _find_and_load_unlocked
  File "<frozen importlib._bootstrap>", line 935, in _load_unlocked
  File "<frozen importlib._bootstrap_external>", line 995, in exec_module
  File "<frozen importlib._bootstrap>", line 488, in _call_with_frames_removed
  File "/home/ec2-user/test_form/wsgi.py", line 1, in <module>
    from app import create_app
  File "/home/ec2-user/test_form/app/__init__.py", line 4, in <module>
    from app.routes import routes
  File "/home/ec2-user/test_form/app/routes.py", line 2, in <module>
    from app.services import users, images, quetions
ImportError: cannot import name 'quetions' from 'app.services' (unknown location)
[2025-01-10 07:07:29 +0000] [55519] [INFO] Worker exiting (pid: 55519)
[2025-01-10 07:07:29 +0000] [55523] [ERROR] Exception in worker process
Traceback (most recent call last):
  File "/home/ec2-user/test_form/.venv/lib64/python3.12/site-packages/gunicorn/arbiter.py", line 608, in spawn_worker
    worker.init_process()
  File "/home/ec2-user/test_form/.venv/lib64/python3.12/site-packages/gunicorn/workers/base.py", line 135, in init_process
    self.load_wsgi()
  File "/home/ec2-user/test_form/.venv/lib64/python3.12/site-packages/gunicorn/workers/base.py", line 147, in load_wsgi
    self.wsgi = self.app.wsgi()
                ^^^^^^^^^^^^^^^
  File "/home/ec2-user/test_form/.venv/lib64/python3.12/site-packages/gunicorn/app/base.py", line 66, in wsgi
    self.callable = self.load()
                    ^^^^^^^^^^^
  File "/home/ec2-user/test_form/.venv/lib64/python3.12/site-packages/gunicorn/app/wsgiapp.py", line 57, in load
    return self.load_wsgiapp()
           ^^^^^^^^^^^^^^^^^^^
  File "/home/ec2-user/test_form/.venv/lib64/python3.12/site-packages/gunicorn/app/wsgiapp.py", line 47, in load_wsgiapp
    return util.import_app(self.app_uri)
           ^^^^^^^^^^^^^^^^^^^^^^^^^^^^^
  File "/home/ec2-user/test_form/.venv/lib64/python3.12/site-packages/gunicorn/util.py", line 370, in import_app
    mod = importlib.import_module(module)
          ^^^^^^^^^^^^^^^^^^^^^^^^^^^^^^^
  File "/usr/lib64/python3.12/importlib/__init__.py", line 90, in import_module
    return _bootstrap._gcd_import(name[level:], package, level)
           ^^^^^^^^^^^^^^^^^^^^^^^^^^^^^^^^^^^^^^^^^^^^^^^^^^^^
  File "<frozen importlib._bootstrap>", line 1387, in _gcd_import
  File "<frozen importlib._bootstrap>", line 1360, in _find_and_load
  File "<frozen importlib._bootstrap>", line 1331, in _find_and_load_unlocked
  File "<frozen importlib._bootstrap>", line 935, in _load_unlocked
  File "<frozen importlib._bootstrap_external>", line 995, in exec_module
  File "<frozen importlib._bootstrap>", line 488, in _call_with_frames_removed
  File "/home/ec2-user/test_form/wsgi.py", line 1, in <module>
    from app import create_app
  File "/home/ec2-user/test_form/app/__init__.py", line 4, in <module>
    from app.routes import routes
  File "/home/ec2-user/test_form/app/routes.py", line 2, in <module>
    from app.services import users, images, quetions
ImportError: cannot import name 'quetions' from 'app.services' (unknown location)
[2025-01-10 07:07:29 +0000] [55523] [INFO] Worker exiting (pid: 55523)
[2025-01-10 07:07:29 +0000] [55522] [ERROR] Exception in worker process
Traceback (most recent call last):
  File "/home/ec2-user/test_form/.venv/lib64/python3.12/site-packages/gunicorn/arbiter.py", line 608, in spawn_worker
    worker.init_process()
  File "/home/ec2-user/test_form/.venv/lib64/python3.12/site-packages/gunicorn/workers/base.py", line 135, in init_process
    self.load_wsgi()
  File "/home/ec2-user/test_form/.venv/lib64/python3.12/site-packages/gunicorn/workers/base.py", line 147, in load_wsgi
    self.wsgi = self.app.wsgi()
                ^^^^^^^^^^^^^^^
  File "/home/ec2-user/test_form/.venv/lib64/python3.12/site-packages/gunicorn/app/base.py", line 66, in wsgi
    self.callable = self.load()
                    ^^^^^^^^^^^
  File "/home/ec2-user/test_form/.venv/lib64/python3.12/site-packages/gunicorn/app/wsgiapp.py", line 57, in load
    return self.load_wsgiapp()
           ^^^^^^^^^^^^^^^^^^^
  File "/home/ec2-user/test_form/.venv/lib64/python3.12/site-packages/gunicorn/app/wsgiapp.py", line 47, in load_wsgiapp
    return util.import_app(self.app_uri)
           ^^^^^^^^^^^^^^^^^^^^^^^^^^^^^
  File "/home/ec2-user/test_form/.venv/lib64/python3.12/site-packages/gunicorn/util.py", line 370, in import_app
    mod = importlib.import_module(module)
          ^^^^^^^^^^^^^^^^^^^^^^^^^^^^^^^
  File "/usr/lib64/python3.12/importlib/__init__.py", line 90, in import_module
    return _bootstrap._gcd_import(name[level:], package, level)
           ^^^^^^^^^^^^^^^^^^^^^^^^^^^^^^^^^^^^^^^^^^^^^^^^^^^^
  File "<frozen importlib._bootstrap>", line 1387, in _gcd_import
  File "<frozen importlib._bootstrap>", line 1360, in _find_and_load
  File "<frozen importlib._bootstrap>", line 1331, in _find_and_load_unlocked
  File "<frozen importlib._bootstrap>", line 935, in _load_unlocked
  File "<frozen importlib._bootstrap_external>", line 995, in exec_module
  File "<frozen importlib._bootstrap>", line 488, in _call_with_frames_removed
  File "/home/ec2-user/test_form/wsgi.py", line 1, in <module>
    from app import create_app
  File "/home/ec2-user/test_form/app/__init__.py", line 4, in <module>
    from app.routes import routes
  File "/home/ec2-user/test_form/app/routes.py", line 2, in <module>
    from app.services import users, images, quetions
ImportError: cannot import name 'quetions' from 'app.services' (unknown location)
[2025-01-10 07:07:29 +0000] [55522] [INFO] Worker exiting (pid: 55522)
[2025-01-10 07:07:29 +0000] [55524] [ERROR] Exception in worker process
Traceback (most recent call last):
  File "/home/ec2-user/test_form/.venv/lib64/python3.12/site-packages/gunicorn/arbiter.py", line 608, in spawn_worker
    worker.init_process()
  File "/home/ec2-user/test_form/.venv/lib64/python3.12/site-packages/gunicorn/workers/base.py", line 135, in init_process
    self.load_wsgi()
  File "/home/ec2-user/test_form/.venv/lib64/python3.12/site-packages/gunicorn/workers/base.py", line 147, in load_wsgi
    self.wsgi = self.app.wsgi()
                ^^^^^^^^^^^^^^^
  File "/home/ec2-user/test_form/.venv/lib64/python3.12/site-packages/gunicorn/app/base.py", line 66, in wsgi
    self.callable = self.load()
                    ^^^^^^^^^^^
  File "/home/ec2-user/test_form/.venv/lib64/python3.12/site-packages/gunicorn/app/wsgiapp.py", line 57, in load
    return self.load_wsgiapp()
           ^^^^^^^^^^^^^^^^^^^
  File "/home/ec2-user/test_form/.venv/lib64/python3.12/site-packages/gunicorn/app/wsgiapp.py", line 47, in load_wsgiapp
    return util.import_app(self.app_uri)
           ^^^^^^^^^^^^^^^^^^^^^^^^^^^^^
  File "/home/ec2-user/test_form/.venv/lib64/python3.12/site-packages/gunicorn/util.py", line 370, in import_app
    mod = importlib.import_module(module)
          ^^^^^^^^^^^^^^^^^^^^^^^^^^^^^^^
  File "/usr/lib64/python3.12/importlib/__init__.py", line 90, in import_module
    return _bootstrap._gcd_import(name[level:], package, level)
           ^^^^^^^^^^^^^^^^^^^^^^^^^^^^^^^^^^^^^^^^^^^^^^^^^^^^
  File "<frozen importlib._bootstrap>", line 1387, in _gcd_import
  File "<frozen importlib._bootstrap>", line 1360, in _find_and_load
  File "<frozen importlib._bootstrap>", line 1331, in _find_and_load_unlocked
  File "<frozen importlib._bootstrap>", line 935, in _load_unlocked
  File "<frozen importlib._bootstrap_external>", line 995, in exec_module
  File "<frozen importlib._bootstrap>", line 488, in _call_with_frames_removed
  File "/home/ec2-user/test_form/wsgi.py", line 1, in <module>
    from app import create_app
  File "/home/ec2-user/test_form/app/__init__.py", line 4, in <module>
    from app.routes import routes
  File "/home/ec2-user/test_form/app/routes.py", line 2, in <module>
    from app.services import users, images, quetions
ImportError: cannot import name 'quetions' from 'app.services' (unknown location)
[2025-01-10 07:07:29 +0000] [55524] [INFO] Worker exiting (pid: 55524)
[2025-01-10 07:07:30 +0000] [55517] [ERROR] Worker (pid:55519) exited with code 3
[2025-01-10 07:07:30 +0000] [55517] [ERROR] Worker (pid:55524) was sent SIGTERM!
[2025-01-10 07:07:30 +0000] [55517] [ERROR] Worker (pid:55523) was sent SIGTERM!
[2025-01-10 07:07:30 +0000] [55517] [ERROR] Worker (pid:55522) was sent SIGTERM!
[2025-01-10 07:07:30 +0000] [55517] [ERROR] Shutting down: Master
[2025-01-10 07:07:30 +0000] [55517] [ERROR] Reason: Worker failed to boot.
